# 2023-03-27 Crash

Service was returning 502 & 503 for about an hour around 4:30 PM PDT / 23:30 UTC

## Lightsail Logs

    [27/Mar/2023:23:32:58] INFO:botocore.credentials:Found credentials in environment variables.
    [27/Mar/2023:23:33:01] /var/lib/news/last-extraction.txt is missing
    [27/Mar/2023:23:35:13] Traceback (most recent call last):
    [27/Mar/2023:23:35:13] File "/usr/lib/python3.10/site-packages/feedparser/util.py", line 156, in __getattr__
    [27/Mar/2023:23:35:13] return self.__getitem__(key)
    [27/Mar/2023:23:35:13] File "/usr/lib/python3.10/site-packages/feedparser/util.py", line 113, in __getitem__
    [27/Mar/2023:23:35:13] return dict.__getitem__(self, key)
    [27/Mar/2023:23:35:13] KeyError: 'status'
    [27/Mar/2023:23:35:13] During handling of the above exception, another exception occurred:
    [27/Mar/2023:23:35:13] Traceback (most recent call last):
    [27/Mar/2023:23:35:13] File "/usr/lib/news/extractor.py", line 76, in <module>
    [27/Mar/2023:23:35:13] main()
    [27/Mar/2023:23:35:13] File "/usr/lib/news/extractor.py", line 57, in main
    [27/Mar/2023:23:35:13] new_count += news.add_new(site.get(now))
    [27/Mar/2023:23:35:13] File "/usr/lib/news/feeds/site.py", line 35, in get
    [27/Mar/2023:23:35:13] if d.status in [200, 302]:
    [27/Mar/2023:23:35:13] File "/usr/lib/python3.10/site-packages/feedparser/util.py", line 158, in __getattr__
    [27/Mar/2023:23:35:13] raise AttributeError("object has no attribute '%s'" % key)
    [27/Mar/2023:23:35:13] AttributeError: object has no attribute 'status'

    [27/Mar/2023:23:35:21] INFO:botocore.credentials:Found credentials in environment variables.
    [27/Mar/2023:23:37:35] Traceback (most recent call last):
    [27/Mar/2023:23:37:35] File "/usr/lib/python3.10/site-packages/feedparser/util.py", line 156, in __getattr__
    [27/Mar/2023:23:37:35] return self.__getitem__(key)
    [27/Mar/2023:23:37:35] File "/usr/lib/python3.10/site-packages/feedparser/util.py", line 113, in __getitem__
    [27/Mar/2023:23:37:35] return dict.__getitem__(self, key)
    [27/Mar/2023:23:37:35] KeyError: 'status'
    [27/Mar/2023:23:37:35] During handling of the above exception, another exception occurred:
    [27/Mar/2023:23:37:35] Traceback (most recent call last):
    [27/Mar/2023:23:37:35] File "/usr/lib/news/extractor.py", line 76, in <module>
    [27/Mar/2023:23:37:35] main()
    [27/Mar/2023:23:37:35] File "/usr/lib/news/extractor.py", line 57, in main
    [27/Mar/2023:23:37:35] new_count += news.add_new(site.get(now))
    [27/Mar/2023:23:37:35] File "/usr/lib/news/feeds/site.py", line 35, in get
    [27/Mar/2023:23:37:35] if d.status in [200, 302]:
    [27/Mar/2023:23:37:35] File "/usr/lib/python3.10/site-packages/feedparser/util.py", line 158, in __getattr__
    [27/Mar/2023:23:37:35] raise AttributeError("object has no attribute '%s'" % key)
    [27/Mar/2023:23:37:35] AttributeError: object has no attribute 'status'

    [27/Mar/2023:23:37:52] INFO:botocore.credentials:Found credentials in environment variables.
    [27/Mar/2023:23:40:07] Traceback (most recent call last):
    [27/Mar/2023:23:40:07] File "/usr/lib/python3.10/site-packages/feedparser/util.py", line 156, in __getattr__
    [27/Mar/2023:23:40:07] return self.__getitem__(key)
    [27/Mar/2023:23:40:07] File "/usr/lib/python3.10/site-packages/feedparser/util.py", line 113, in __getitem__
    [27/Mar/2023:23:40:07] return dict.__getitem__(self, key)
    [27/Mar/2023:23:40:07] KeyError: 'status'
    [27/Mar/2023:23:40:07] During handling of the above exception, another exception occurred:
    [27/Mar/2023:23:40:07] Traceback (most recent call last):
    [27/Mar/2023:23:40:07] File "/usr/lib/news/extractor.py", line 76, in <module>
    [27/Mar/2023:23:40:07] main()
    [27/Mar/2023:23:40:07] File "/usr/lib/news/extractor.py", line 57, in main
    [27/Mar/2023:23:40:07] new_count += news.add_new(site.get(now))
    [27/Mar/2023:23:40:07] File "/usr/lib/news/feeds/site.py", line 35, in get
    [27/Mar/2023:23:40:07] if d.status in [200, 302]:
    [27/Mar/2023:23:40:07] File "/usr/lib/python3.10/site-packages/feedparser/util.py", line 158, in __getattr__
    [27/Mar/2023:23:40:07] raise AttributeError("object has no attribute '%s'" % key)
    [27/Mar/2023:23:40:07] AttributeError: object has no attribute 'status'

    [27/Mar/2023:23:40:23] INFO:botocore.credentials:Found credentials in environment variables.
    [27/Mar/2023:23:42:37] Traceback (most recent call last):
    [27/Mar/2023:23:42:37] File "/usr/lib/python3.10/site-packages/feedparser/util.py", line 156, in __getattr__
    [27/Mar/2023:23:42:37] return self.__getitem__(key)
    [27/Mar/2023:23:42:37] File "/usr/lib/python3.10/site-packages/feedparser/util.py", line 113, in __getitem__
    [27/Mar/2023:23:42:37] return dict.__getitem__(self, key)
    [27/Mar/2023:23:42:37] KeyError: 'status'
    [27/Mar/2023:23:42:37] During handling of the above exception, another exception occurred:
    [27/Mar/2023:23:42:37] Traceback (most recent call last):
    [27/Mar/2023:23:42:37] File "/usr/lib/news/extractor.py", line 76, in <module>
    [27/Mar/2023:23:42:37] main()
    [27/Mar/2023:23:42:37] File "/usr/lib/news/extractor.py", line 57, in main
    [27/Mar/2023:23:42:37] new_count += news.add_new(site.get(now))
    [27/Mar/2023:23:42:37] File "/usr/lib/news/feeds/site.py", line 35, in get
    [27/Mar/2023:23:42:37] if d.status in [200, 302]:
    [27/Mar/2023:23:42:37] File "/usr/lib/python3.10/site-packages/feedparser/util.py", line 158, in __getattr__
    [27/Mar/2023:23:42:37] raise AttributeError("object has no attribute '%s'" % key)
    [27/Mar/2023:23:42:37] AttributeError: object has no attribute 'status'

    [27/Mar/2023:23:42:49] INFO:botocore.credentials:Found credentials in environment variables.
    [27/Mar/2023:23:43:01] /var/lib/news/last-extraction.txt is missing
    [27/Mar/2023:23:45:04] Traceback (most recent call last):
    [27/Mar/2023:23:45:04] File "/usr/lib/python3.10/site-packages/feedparser/util.py", line 156, in __getattr__
    [27/Mar/2023:23:45:04] return self.__getitem__(key)
    [27/Mar/2023:23:45:04] File "/usr/lib/python3.10/site-packages/feedparser/util.py", line 113, in __getitem__
    [27/Mar/2023:23:45:04] return dict.__getitem__(self, key)
    [27/Mar/2023:23:45:04] KeyError: 'status'
    [27/Mar/2023:23:45:04] During handling of the above exception, another exception occurred:
    [27/Mar/2023:23:45:04] Traceback (most recent call last):
    [27/Mar/2023:23:45:04] File "/usr/lib/news/extractor.py", line 76, in <module>
    [27/Mar/2023:23:45:04] main()
    [27/Mar/2023:23:45:04] File "/usr/lib/news/extractor.py", line 57, in main
    [27/Mar/2023:23:45:04] new_count += news.add_new(site.get(now))
    [27/Mar/2023:23:45:04] File "/usr/lib/news/feeds/site.py", line 35, in get
    [27/Mar/2023:23:45:04] if d.status in [200, 302]:
    [27/Mar/2023:23:45:04] File "/usr/lib/python3.10/site-packages/feedparser/util.py", line 158, in __getattr__
    [27/Mar/2023:23:45:04] raise AttributeError("object has no attribute '%s'" % key)
    [27/Mar/2023:23:45:04] AttributeError: object has no attribute 'status'

    [27/Mar/2023:23:45:12] INFO:botocore.credentials:Found credentials in environment variables.
    [27/Mar/2023:23:47:25] Traceback (most recent call last):
    [27/Mar/2023:23:47:25] File "/usr/lib/python3.10/site-packages/feedparser/util.py", line 156, in __getattr__
    [27/Mar/2023:23:47:25] return self.__getitem__(key)
    [27/Mar/2023:23:47:25] File "/usr/lib/python3.10/site-packages/feedparser/util.py", line 113, in __getitem__
    [27/Mar/2023:23:47:25] return dict.__getitem__(self, key)
    [27/Mar/2023:23:47:25] KeyError: 'status'
    [27/Mar/2023:23:47:25] During handling of the above exception, another exception occurred:
    [27/Mar/2023:23:47:25] Traceback (most recent call last):
    [27/Mar/2023:23:47:25] File "/usr/lib/news/extractor.py", line 76, in <module>
    [27/Mar/2023:23:47:25] main()
    [27/Mar/2023:23:47:25] File "/usr/lib/news/extractor.py", line 57, in main
    [27/Mar/2023:23:47:25] new_count += news.add_new(site.get(now))
    [27/Mar/2023:23:47:25] File "/usr/lib/news/feeds/site.py", line 35, in get
    [27/Mar/2023:23:47:25] if d.status in [200, 302]:
    [27/Mar/2023:23:47:25] File "/usr/lib/python3.10/site-packages/feedparser/util.py", line 158, in __getattr__
    [27/Mar/2023:23:47:25] raise AttributeError("object has no attribute '%s'" % key)
    [27/Mar/2023:23:47:25] AttributeError: object has no attribute 'status'

    [27/Mar/2023:23:47:38] INFO:botocore.credentials:Found credentials in environment variables.
    [27/Mar/2023:23:49:51] Traceback (most recent call last):
    [27/Mar/2023:23:49:51] File "/usr/lib/python3.10/site-packages/feedparser/util.py", line 156, in __getattr__
    [27/Mar/2023:23:49:51] return self.__getitem__(key)
    [27/Mar/2023:23:49:51] File "/usr/lib/python3.10/site-packages/feedparser/util.py", line 113, in __getitem__
    [27/Mar/2023:23:49:51] return dict.__getitem__(self, key)
    [27/Mar/2023:23:49:51] KeyError: 'status'
    [27/Mar/2023:23:49:51] During handling of the above exception, another exception occurred:
    [27/Mar/2023:23:49:51] Traceback (most recent call last):
    [27/Mar/2023:23:49:51] File "/usr/lib/news/extractor.py", line 76, in <module>
    [27/Mar/2023:23:49:51] main()
    [27/Mar/2023:23:49:51] File "/usr/lib/news/extractor.py", line 57, in main
    [27/Mar/2023:23:49:51] new_count += news.add_new(site.get(now))
    [27/Mar/2023:23:49:51] File "/usr/lib/news/feeds/site.py", line 35, in get
    [27/Mar/2023:23:49:51] if d.status in [200, 302]:
    [27/Mar/2023:23:49:51] File "/usr/lib/python3.10/site-packages/feedparser/util.py", line 158, in __getattr__
    [27/Mar/2023:23:49:51] raise AttributeError("object has no attribute '%s'" % key)
    [27/Mar/2023:23:49:51] AttributeError: object has no attribute 'status'
    [27/Mar/2023:23:50:02] /var/lib/news/last-extraction.txt is missing

    [27/Mar/2023:23:50:02] INFO:botocore.credentials:Found credentials in environment variables.

    [27/Mar/2023:23:50:08] INFO:botocore.credentials:Found credentials in environment variables.
    [27/Mar/2023:23:52:23] Traceback (most recent call last):
    [27/Mar/2023:23:52:23] File "/usr/lib/python3.10/site-packages/feedparser/util.py", line 156, in __getattr__
    [27/Mar/2023:23:52:23] return self.__getitem__(key)
    [27/Mar/2023:23:52:23] File "/usr/lib/python3.10/site-packages/feedparser/util.py", line 113, in __getitem__
    [27/Mar/2023:23:52:23] return dict.__getitem__(self, key)
    [27/Mar/2023:23:52:23] KeyError: 'status'
    [27/Mar/2023:23:52:23] During handling of the above exception, another exception occurred:
    [27/Mar/2023:23:52:23] Traceback (most recent call last):
    [27/Mar/2023:23:52:23] File "/usr/lib/news/extractor.py", line 76, in <module>
    [27/Mar/2023:23:52:23] main()
    [27/Mar/2023:23:52:23] File "/usr/lib/news/extractor.py", line 57, in main
    [27/Mar/2023:23:52:23] new_count += news.add_new(site.get(now))
    [27/Mar/2023:23:52:23] File "/usr/lib/news/feeds/site.py", line 35, in get
    [27/Mar/2023:23:52:23] if d.status in [200, 302]:
    [27/Mar/2023:23:52:23] File "/usr/lib/python3.10/site-packages/feedparser/util.py", line 158, in __getattr__
    [27/Mar/2023:23:52:23] raise AttributeError("object has no attribute '%s'" % key)
    [27/Mar/2023:23:52:23] AttributeError: object has no attribute 'status'

    [27/Mar/2023:23:52:37] INFO:botocore.credentials:Found credentials in environment variables.
    [27/Mar/2023:23:54:52] Traceback (most recent call last):
    [27/Mar/2023:23:54:52] File "/usr/lib/python3.10/site-packages/feedparser/util.py", line 156, in __getattr__
    [27/Mar/2023:23:54:52] return self.__getitem__(key)
    [27/Mar/2023:23:54:52] File "/usr/lib/python3.10/site-packages/feedparser/util.py", line 113, in __getitem__
    [27/Mar/2023:23:54:52] return dict.__getitem__(self, key)
    [27/Mar/2023:23:54:52] KeyError: 'status'
    [27/Mar/2023:23:54:52] During handling of the above exception, another exception occurred:
    [27/Mar/2023:23:54:52] Traceback (most recent call last):
    [27/Mar/2023:23:54:52] File "/usr/lib/news/extractor.py", line 76, in <module>
    [27/Mar/2023:23:54:52] main()
    [27/Mar/2023:23:54:52] File "/usr/lib/news/extractor.py", line 57, in main
    [27/Mar/2023:23:54:52] new_count += news.add_new(site.get(now))
    [27/Mar/2023:23:54:52] File "/usr/lib/news/feeds/site.py", line 35, in get
    [27/Mar/2023:23:54:52] if d.status in [200, 302]:
    [27/Mar/2023:23:54:52] File "/usr/lib/python3.10/site-packages/feedparser/util.py", line 158, in __getattr__
    [27/Mar/2023:23:54:52] raise AttributeError("object has no attribute '%s'" % key)
    [27/Mar/2023:23:54:52] AttributeError: object has no attribute 'status'

    [27/Mar/2023:23:55:02] INFO:botocore.credentials:Found credentials in environment variables.
    [27/Mar/2023:23:55:03] /var/lib/news/last-extraction.txt is missing

    [27/Mar/2023:23:55:03] INFO:botocore.credentials:Found credentials in environment variables.

    [27/Mar/2023:23:57:07] INFO:botocore.credentials:Found credentials in environment variables.
    [27/Mar/2023:23:57:16] Traceback (most recent call last):
    [27/Mar/2023:23:57:16] File "/usr/lib/python3.10/site-packages/feedparser/util.py", line 156, in __getattr__
    [27/Mar/2023:23:57:16] return self.__getitem__(key)
    [27/Mar/2023:23:57:16] File "/usr/lib/python3.10/site-packages/feedparser/util.py", line 113, in __getitem__
    [27/Mar/2023:23:57:16] return dict.__getitem__(self, key)
    [27/Mar/2023:23:57:16] KeyError: 'status'
    [27/Mar/2023:23:57:16] During handling of the above exception, another exception occurred:
    [27/Mar/2023:23:57:16] Traceback (most recent call last):
    [27/Mar/2023:23:57:16] File "/usr/lib/news/extractor.py", line 76, in <module>
    [27/Mar/2023:23:57:16] main()
    [27/Mar/2023:23:57:16] File "/usr/lib/news/extractor.py", line 57, in main
    [27/Mar/2023:23:57:16] new_count += news.add_new(site.get(now))
    [27/Mar/2023:23:57:16] File "/usr/lib/news/feeds/site.py", line 35, in get
    [27/Mar/2023:23:57:16] if d.status in [200, 302]:
    [27/Mar/2023:23:57:16] File "/usr/lib/python3.10/site-packages/feedparser/util.py", line 158, in __getattr__
    [27/Mar/2023:23:57:16] raise AttributeError("object has no attribute '%s'" % key)
    [27/Mar/2023:23:57:16] AttributeError: object has no attribute 'status'

    [27/Mar/2023:23:59:21] Traceback (most recent call last):
    [27/Mar/2023:23:59:21] File "/usr/lib/python3.10/site-packages/feedparser/util.py", line 156, in __getattr__
    [27/Mar/2023:23:59:21] return self.__getitem__(key)
    [27/Mar/2023:23:59:21] File "/usr/lib/python3.10/site-packages/feedparser/util.py", line 113, in __getitem__
    [27/Mar/2023:23:59:21] return dict.__getitem__(self, key)
    [27/Mar/2023:23:59:21] KeyError: 'status'
    [27/Mar/2023:23:59:21] During handling of the above exception, another exception occurred:
    [27/Mar/2023:23:59:21] Traceback (most recent call last):
    [27/Mar/2023:23:59:21] File "/usr/lib/news/extractor.py", line 76, in <module>
    [27/Mar/2023:23:59:21] main()
    [27/Mar/2023:23:59:21] File "/usr/lib/news/extractor.py", line 57, in main
    [27/Mar/2023:23:59:21] new_count += news.add_new(site.get(now))
    [27/Mar/2023:23:59:21] File "/usr/lib/news/feeds/site.py", line 35, in get
    [27/Mar/2023:23:59:21] if d.status in [200, 302]:
    [27/Mar/2023:23:59:21] File "/usr/lib/python3.10/site-packages/feedparser/util.py", line 158, in __getattr__
    [27/Mar/2023:23:59:21] raise AttributeError("object has no attribute '%s'" % key)
    [27/Mar/2023:23:59:21] AttributeError: object has no attribute 'status'

    [27/Mar/2023:23:59:33] INFO:botocore.credentials:Found credentials in environment variables.
    [28/Mar/2023:00:01:48] Traceback (most recent call last):
    [28/Mar/2023:00:01:48] File "/usr/lib/python3.10/site-packages/feedparser/util.py", line 156, in __getattr__
    [28/Mar/2023:00:01:48] return self.__getitem__(key)
    [28/Mar/2023:00:01:48] File "/usr/lib/python3.10/site-packages/feedparser/util.py", line 113, in __getitem__
    [28/Mar/2023:00:01:48] return dict.__getitem__(self, key)
    [28/Mar/2023:00:01:48] KeyError: 'status'
    [28/Mar/2023:00:01:48] During handling of the above exception, another exception occurred:
    [28/Mar/2023:00:01:48] Traceback (most recent call last):
    [28/Mar/2023:00:01:48] File "/usr/lib/news/extractor.py", line 76, in <module>
    [28/Mar/2023:00:01:48] main()
    [28/Mar/2023:00:01:48] File "/usr/lib/news/extractor.py", line 57, in main
    [28/Mar/2023:00:01:48] new_count += news.add_new(site.get(now))
    [28/Mar/2023:00:01:48] File "/usr/lib/news/feeds/site.py", line 35, in get
    [28/Mar/2023:00:01:48] if d.status in [200, 302]:
    [28/Mar/2023:00:01:48] File "/usr/lib/python3.10/site-packages/feedparser/util.py", line 158, in __getattr__
    [28/Mar/2023:00:01:48] raise AttributeError("object has no attribute '%s'" % key)
    [28/Mar/2023:00:01:48] AttributeError: object has no attribute 'status'
    [28/Mar/2023:00:02:00] /var/lib/news/last-extraction.txt is missing

    [28/Mar/2023:00:02:17] INFO:botocore.credentials:Found credentials in environment variables.
    [28/Mar/2023:00:04:32] Traceback (most recent call last):
    [28/Mar/2023:00:04:32] File "/usr/lib/python3.10/site-packages/feedparser/util.py", line 156, in __getattr__
    [28/Mar/2023:00:04:32] return self.__getitem__(key)
    [28/Mar/2023:00:04:32] File "/usr/lib/python3.10/site-packages/feedparser/util.py", line 113, in __getitem__
    [28/Mar/2023:00:04:32] return dict.__getitem__(self, key)
    [28/Mar/2023:00:04:32] KeyError: 'status'
    [28/Mar/2023:00:04:32] During handling of the above exception, another exception occurred:
    [28/Mar/2023:00:04:32] Traceback (most recent call last):
    [28/Mar/2023:00:04:32] File "/usr/lib/news/extractor.py", line 76, in <module>
    [28/Mar/2023:00:04:32] main()
    [28/Mar/2023:00:04:32] File "/usr/lib/news/extractor.py", line 57, in main
    [28/Mar/2023:00:04:32] new_count += news.add_new(site.get(now))
    [28/Mar/2023:00:04:32] File "/usr/lib/news/feeds/site.py", line 35, in get
    [28/Mar/2023:00:04:32] if d.status in [200, 302]:
    [28/Mar/2023:00:04:32] File "/usr/lib/python3.10/site-packages/feedparser/util.py", line 158, in __getattr__
    [28/Mar/2023:00:04:32] raise AttributeError("object has no attribute '%s'" % key)
    [28/Mar/2023:00:04:32] AttributeError: object has no attribute 'status'

    [28/Mar/2023:00:04:45] INFO:botocore.credentials:Found credentials in environment variables.
    [28/Mar/2023:00:07:00] Traceback (most recent call last):
    [28/Mar/2023:00:07:00] File "/usr/lib/python3.10/site-packages/feedparser/util.py", line 156, in __getattr__
    [28/Mar/2023:00:07:00] return self.__getitem__(key)
    [28/Mar/2023:00:07:00] File "/usr/lib/python3.10/site-packages/feedparser/util.py", line 113, in __getitem__
    [28/Mar/2023:00:07:00] return dict.__getitem__(self, key)
    [28/Mar/2023:00:07:00] KeyError: 'status'
    [28/Mar/2023:00:07:00] During handling of the above exception, another exception occurred:
    [28/Mar/2023:00:07:00] Traceback (most recent call last):
    [28/Mar/2023:00:07:00] File "/usr/lib/news/extractor.py", line 76, in <module>
    [28/Mar/2023:00:07:00] main()
    [28/Mar/2023:00:07:00] File "/usr/lib/news/extractor.py", line 57, in main
    [28/Mar/2023:00:07:00] new_count += news.add_new(site.get(now))
    [28/Mar/2023:00:07:00] File "/usr/lib/news/feeds/site.py", line 35, in get
    [28/Mar/2023:00:07:00] if d.status in [200, 302]:
    [28/Mar/2023:00:07:00] File "/usr/lib/python3.10/site-packages/feedparser/util.py", line 158, in __getattr__
    [28/Mar/2023:00:07:00] raise AttributeError("object has no attribute '%s'" % key)
    [28/Mar/2023:00:07:00] AttributeError: object has no attribute 'status'

    [28/Mar/2023:00:07:11] INFO:botocore.credentials:Found credentials in environment variables.
    [28/Mar/2023:00:09:24] Traceback (most recent call last):
    [28/Mar/2023:00:09:24] File "/usr/lib/python3.10/site-packages/feedparser/util.py", line 156, in __getattr__
    [28/Mar/2023:00:09:24] return self.__getitem__(key)
    [28/Mar/2023:00:09:24] File "/usr/lib/python3.10/site-packages/feedparser/util.py", line 113, in __getitem__
    [28/Mar/2023:00:09:24] return dict.__getitem__(self, key)
    [28/Mar/2023:00:09:24] KeyError: 'status'
    [28/Mar/2023:00:09:24] During handling of the above exception, another exception occurred:
    [28/Mar/2023:00:09:24] Traceback (most recent call last):
    [28/Mar/2023:00:09:24] File "/usr/lib/news/extractor.py", line 76, in <module>
    [28/Mar/2023:00:09:24] main()
    [28/Mar/2023:00:09:24] File "/usr/lib/news/extractor.py", line 57, in main
    [28/Mar/2023:00:09:24] new_count += news.add_new(site.get(now))
    [28/Mar/2023:00:09:24] File "/usr/lib/news/feeds/site.py", line 35, in get
    [28/Mar/2023:00:09:24] if d.status in [200, 302]:
    [28/Mar/2023:00:09:24] File "/usr/lib/python3.10/site-packages/feedparser/util.py", line 158, in __getattr__
    [28/Mar/2023:00:09:24] raise AttributeError("object has no attribute '%s'" % key)
    [28/Mar/2023:00:09:24] AttributeError: object has no attribute 'status'

    [28/Mar/2023:00:09:36] INFO:botocore.credentials:Found credentials in environment variables.
    [28/Mar/2023:00:11:51] Traceback (most recent call last):
    [28/Mar/2023:00:11:51] File "/usr/lib/python3.10/site-packages/feedparser/util.py", line 156, in __getattr__
    [28/Mar/2023:00:11:51] return self.__getitem__(key)
    [28/Mar/2023:00:11:51] File "/usr/lib/python3.10/site-packages/feedparser/util.py", line 113, in __getitem__
    [28/Mar/2023:00:11:51] return dict.__getitem__(self, key)
    [28/Mar/2023:00:11:51] KeyError: 'status'
    [28/Mar/2023:00:11:51] During handling of the above exception, another exception occurred:
    [28/Mar/2023:00:11:51] Traceback (most recent call last):
    [28/Mar/2023:00:11:51] File "/usr/lib/news/extractor.py", line 76, in <module>
    [28/Mar/2023:00:11:51] main()
    [28/Mar/2023:00:11:51] File "/usr/lib/news/extractor.py", line 57, in main
    [28/Mar/2023:00:11:51] new_count += news.add_new(site.get(now))
    [28/Mar/2023:00:11:51] File "/usr/lib/news/feeds/site.py", line 35, in get
    [28/Mar/2023:00:11:51] if d.status in [200, 302]:
    [28/Mar/2023:00:11:51] File "/usr/lib/python3.10/site-packages/feedparser/util.py", line 158, in __getattr__
    [28/Mar/2023:00:11:51] raise AttributeError("object has no attribute '%s'" % key)
    [28/Mar/2023:00:11:51] AttributeError: object has no attribute 'status'
    [28/Mar/2023:00:12:01] /var/lib/news/last-extraction.txt is missing

    [28/Mar/2023:00:12:03] INFO:botocore.credentials:Found credentials in environment variables.
    [28/Mar/2023:00:14:17] Traceback (most recent call last):
    [28/Mar/2023:00:14:17] File "/usr/lib/python3.10/site-packages/feedparser/util.py", line 156, in __getattr__
    [28/Mar/2023:00:14:17] return self.__getitem__(key)
    [28/Mar/2023:00:14:17] File "/usr/lib/python3.10/site-packages/feedparser/util.py", line 113, in __getitem__
    [28/Mar/2023:00:14:17] return dict.__getitem__(self, key)
    [28/Mar/2023:00:14:17] KeyError: 'status'
    [28/Mar/2023:00:14:17] During handling of the above exception, another exception occurred:
    [28/Mar/2023:00:14:17] Traceback (most recent call last):
    [28/Mar/2023:00:14:17] File "/usr/lib/news/extractor.py", line 76, in <module>
    [28/Mar/2023:00:14:17] main()
    [28/Mar/2023:00:14:17] File "/usr/lib/news/extractor.py", line 57, in main
    [28/Mar/2023:00:14:17] new_count += news.add_new(site.get(now))
    [28/Mar/2023:00:14:17] File "/usr/lib/news/feeds/site.py", line 35, in get
    [28/Mar/2023:00:14:17] if d.status in [200, 302]:
    [28/Mar/2023:00:14:17] File "/usr/lib/python3.10/site-packages/feedparser/util.py", line 158, in __getattr__
    [28/Mar/2023:00:14:17] raise AttributeError("object has no attribute '%s'" % key)
    [28/Mar/2023:00:14:17] AttributeError: object has no attribute 'status'

    [28/Mar/2023:00:14:45] INFO:botocore.credentials:Found credentials in environment variables.
    [28/Mar/2023:00:16:59] Traceback (most recent call last):
    [28/Mar/2023:00:16:59] File "/usr/lib/python3.10/site-packages/feedparser/util.py", line 156, in __getattr__
    [28/Mar/2023:00:16:59] return self.__getitem__(key)
    [28/Mar/2023:00:16:59] File "/usr/lib/python3.10/site-packages/feedparser/util.py", line 113, in __getitem__
    [28/Mar/2023:00:16:59] return dict.__getitem__(self, key)
    [28/Mar/2023:00:16:59] KeyError: 'status'
    [28/Mar/2023:00:16:59] During handling of the above exception, another exception occurred:
    [28/Mar/2023:00:16:59] Traceback (most recent call last):
    [28/Mar/2023:00:16:59] File "/usr/lib/news/extractor.py", line 76, in <module>
    [28/Mar/2023:00:16:59] main()
    [28/Mar/2023:00:16:59] File "/usr/lib/news/extractor.py", line 57, in main
    [28/Mar/2023:00:16:59] new_count += news.add_new(site.get(now))
    [28/Mar/2023:00:16:59] File "/usr/lib/news/feeds/site.py", line 35, in get
    [28/Mar/2023:00:16:59] if d.status in [200, 302]:
    [28/Mar/2023:00:16:59] File "/usr/lib/python3.10/site-packages/feedparser/util.py", line 158, in __getattr__
    [28/Mar/2023:00:16:59] raise AttributeError("object has no attribute '%s'" % key)
    [28/Mar/2023:00:16:59] AttributeError: object has no attribute 'status'

    [28/Mar/2023:00:17:25] INFO:botocore.credentials:Found credentials in environment variables.
    [28/Mar/2023:00:19:39] Traceback (most recent call last):
    [28/Mar/2023:00:19:39] File "/usr/lib/python3.10/site-packages/feedparser/util.py", line 156, in __getattr__
    [28/Mar/2023:00:19:39] return self.__getitem__(key)
    [28/Mar/2023:00:19:39] File "/usr/lib/python3.10/site-packages/feedparser/util.py", line 113, in __getitem__
    [28/Mar/2023:00:19:39] return dict.__getitem__(self, key)
    [28/Mar/2023:00:19:39] KeyError: 'status'
    [28/Mar/2023:00:19:39] During handling of the above exception, another exception occurred:
    [28/Mar/2023:00:19:39] Traceback (most recent call last):
    [28/Mar/2023:00:19:39] File "/usr/lib/news/extractor.py", line 76, in <module>
    [28/Mar/2023:00:19:39] main()
    [28/Mar/2023:00:19:39] File "/usr/lib/news/extractor.py", line 57, in main
    [28/Mar/2023:00:19:39] new_count += news.add_new(site.get(now))
    [28/Mar/2023:00:19:39] File "/usr/lib/news/feeds/site.py", line 35, in get
    [28/Mar/2023:00:19:39] if d.status in [200, 302]:
    [28/Mar/2023:00:19:39] File "/usr/lib/python3.10/site-packages/feedparser/util.py", line 158, in __getattr__
    [28/Mar/2023:00:19:39] raise AttributeError("object has no attribute '%s'" % key)
    [28/Mar/2023:00:19:39] AttributeError: object has no attribute 'status'

    [28/Mar/2023:00:19:56] INFO:botocore.credentials:Found credentials in environment variables.
    [28/Mar/2023:00:20:02] /var/lib/news/last-extraction.txt is missing

    [28/Mar/2023:00:20:03] INFO:botocore.credentials:Found credentials in environment variables.
    [28/Mar/2023:00:22:11] Traceback (most recent call last):
    [28/Mar/2023:00:22:11] File "/usr/lib/python3.10/site-packages/feedparser/util.py", line 156, in __getattr__
    [28/Mar/2023:00:22:11] return self.__getitem__(key)
    [28/Mar/2023:00:22:11] File "/usr/lib/python3.10/site-packages/feedparser/util.py", line 113, in __getitem__
    [28/Mar/2023:00:22:11] return dict.__getitem__(self, key)
    [28/Mar/2023:00:22:11] KeyError: 'status'
    [28/Mar/2023:00:22:11] During handling of the above exception, another exception occurred:
    [28/Mar/2023:00:22:11] Traceback (most recent call last):
    [28/Mar/2023:00:22:11] File "/usr/lib/news/extractor.py", line 76, in <module>
    [28/Mar/2023:00:22:11] main()
    [28/Mar/2023:00:22:11] File "/usr/lib/news/extractor.py", line 57, in main
    [28/Mar/2023:00:22:11] new_count += news.add_new(site.get(now))
    [28/Mar/2023:00:22:11] File "/usr/lib/news/feeds/site.py", line 35, in get
    [28/Mar/2023:00:22:11] if d.status in [200, 302]:
    [28/Mar/2023:00:22:11] File "/usr/lib/python3.10/site-packages/feedparser/util.py", line 158, in __getattr__
    [28/Mar/2023:00:22:11] raise AttributeError("object has no attribute '%s'" % key)
    [28/Mar/2023:00:22:11] AttributeError: object has no attribute 'status'

    [28/Mar/2023:00:22:22] INFO:botocore.credentials:Found credentials in environment variables.
    [28/Mar/2023:00:22:29] INFO:extractor.py:Added 3 and removed 5 items.

    [28/Mar/2023:00:25:02] INFO:botocore.credentials:Found credentials in environment variables.
    [28/Mar/2023:00:25:06] INFO:extractor.py:Added 0 and removed 0 items.

    [28/Mar/2023:00:30:03] INFO:botocore.credentials:Found credentials in environment variables.
    [28/Mar/2023:00:30:06] INFO:extractor.py:Added 0 and removed 0 items.

    [28/Mar/2023:00:35:02] INFO:botocore.credentials:Found credentials in environment variables.
    [28/Mar/2023:00:35:06] INFO:extractor.py:Added 0 and removed 0 items.

    [28/Mar/2023:00:40:02] INFO:botocore.credentials:Found credentials in environment variables.
    [28/Mar/2023:00:40:06] INFO:extractor.py:Added 0 and removed 0 items.
